[cef_embedded.py] CEF Python 66.1
[cef_embedded.py] Python 3.9.13 64bit
[cef_embedded.py] Tk 8.6.12

DevTools listening on ws://127.0.0.1:51782/devtools/browser/a1573651-b30d-427d-9392-b3b6d6c43d78
Exception in Tkinter callback
Traceback (most recent call last):
  File "C:\Users\gwurm\anaconda3\envs\RegressionExplorer\lib\site-packages\pandas\core\indexes\base.py", line 3621, in get_loc
    return self._engine.get_loc(casted_key)
  File "pandas\_libs\index.pyx", line 136, in pandas._libs.index.IndexEngine.get_loc
  File "pandas\_libs\index.pyx", line 163, in pandas._libs.index.IndexEngine.get_loc
  File "pandas\_libs\hashtable_class_helper.pxi", line 5198, in pandas._libs.hashtable.PyObjectHashTable.get_item
  File "pandas\_libs\hashtable_class_helper.pxi", line 5206, in pandas._libs.hashtable.PyObjectHashTable.get_item
KeyError: 'origin'

The above exception was the direct cause of the following exception:

Traceback (most recent call last):
  File "C:\Users\gwurm\anaconda3\envs\RegressionExplorer\lib\tkinter\__init__.py", line 1892, in __call__
    return self.func(*args)
  File "C:\Users\gwurm\Desktop\Projects\RegressionExplorer\GUI\explorer_gui_support.py", line 141, in create_pairplot
    fig = sns.pairplot(data=_data['df_pairplot'], hue=hue).figure
  File "C:\Users\gwurm\anaconda3\envs\RegressionExplorer\lib\site-packages\seaborn\_decorators.py", line 46, in inner_f
    return f(**kwargs)
  File "C:\Users\gwurm\anaconda3\envs\RegressionExplorer\lib\site-packages\seaborn\axisgrid.py", line 2096, in pairplot
    grid = PairGrid(data, vars=vars, x_vars=x_vars, y_vars=y_vars, hue=hue,
  File "C:\Users\gwurm\anaconda3\envs\RegressionExplorer\lib\site-packages\seaborn\_decorators.py", line 46, in inner_f
    return f(**kwargs)
  File "C:\Users\gwurm\anaconda3\envs\RegressionExplorer\lib\site-packages\seaborn\axisgrid.py", line 1289, in __init__
    hue_names = hue_order = categorical_order(data[hue], hue_order)
  File "C:\Users\gwurm\anaconda3\envs\RegressionExplorer\lib\site-packages\pandas\core\frame.py", line 3505, in __getitem__
    indexer = self.columns.get_loc(key)
  File "C:\Users\gwurm\anaconda3\envs\RegressionExplorer\lib\site-packages\pandas\core\indexes\base.py", line 3623, in get_loc
    raise KeyError(key) from err
KeyError: 'origin'
